<sdf version='1.6'>
  <model name='karcher_urdf'>
    <link name='chassis'>
      <pose frame=''>0 0 0 0 -0 0</pose>
      <inertial>
        <pose frame=''>0 0 0 0 -0 0</pose>
        <mass>725</mass>
        <inertia>
          <ixx>322.8</ixx>
          <ixy>0</ixy>
          <ixz>0</ixz>
          <iyy>221.43</iyy>
          <iyz>0</iyz>
          <izz>290.15</izz>
        </inertia>
      </inertial>
      <collision name='chassis_collision_collision'>
        <pose frame=''>0 0 0.09 0 -0 0</pose>
        <geometry>
          <mesh>
            <scale>0.1 0.1 0.1</scale>
            <uri>model://karcher_urdf/meshes/karcher_model.dae</uri>
          </mesh>
        </geometry>
      </collision>
      <visual name='chassis_visual_visual'>
        <pose frame=''>0 0 0.09 0 -0 0</pose>
        <geometry>
          <mesh>
            <scale>0.1 0.1 0.1</scale>
            <uri>model://karcher_urdf/meshes/karcher_model.dae</uri>
          </mesh>
        </geometry>
      </visual>
    </link>
    <link name='front_dummy_link'>
      <pose frame=''>0 0.08 0.0175 0 0.000019 0</pose>
      <inertial>
        <pose frame=''>0 0 0 0 -0 0</pose>
        <mass>0.1</mass>
        <inertia>
          <ixx>0</ixx>
          <ixy>0</ixy>
          <ixz>0</ixz>
          <iyy>0</iyy>
          <iyz>0</iyz>
          <izz>0</izz>
        </inertia>
      </inertial>
    </link>
    <joint name='front_steer_joint' type='revolute'>
      <child>front_dummy_link</child>
      <parent>chassis</parent>
      <axis>
        <xyz>0.000019 0 1</xyz>
        <limit>
          <lower>-1.5707</lower>
          <upper>1.5707</upper>
          <effort>1000</effort>
          <velocity>100</velocity>
        </limit>
        <dynamics>
          <spring_reference>0</spring_reference>
          <spring_stiffness>0</spring_stiffness>
        </dynamics>
        <use_parent_model_frame>1</use_parent_model_frame>
      </axis>
    </joint>
    <link name='front_wheel'>
      <pose frame=''>0 0.08 0.0175 0 0.000019 0</pose>
      <inertial>
        <pose frame=''>0 0 0 0 -0 0</pose>
        <mass>5</mass>
        <inertia>
          <ixx>0.02917</ixx>
          <ixy>0</ixy>
          <ixz>0</ixz>
          <iyy>0.02917</iyy>
          <iyz>0</iyz>
          <izz>0.025</izz>
        </inertia>
      </inertial>
      <collision name='front_wheel_collision_collision'>
        <pose frame=''>0 0 0 0.314159 -0.157079 0.314159</pose>
        <geometry>
          <sphere>
            <radius>0.01</radius>
          </sphere>
        </geometry>
      </collision>
      <visual name='front_wheel_visual_visual'>
        <pose frame=''>0 0 0 0.314159 -0.157079 0.314159</pose>
        <geometry>
          <cylinder>
            <length>0.02</length>
            <radius>0.01</radius>
          </cylinder>
        </geometry>
      </visual>
    </link>
    <joint name='front_wheel_joint' type='revolute'>
      <child>front_wheel</child>
      <parent>front_dummy_link</parent>
      <axis>
        <xyz>0.1 0 -0.000019</xyz>
        <limit>
          <lower>-1e+16</lower>
          <upper>1e+16</upper>
        </limit>
        <dynamics>
          <spring_reference>0</spring_reference>
          <spring_stiffness>0</spring_stiffness>
        </dynamics>
        <use_parent_model_frame>1</use_parent_model_frame>
      </axis>
    </joint>
    <link name='rear_left_wheel'>
      <pose frame=''>-0.05742 -0.065 0.0275 0.314159 0.000019 0.314159</pose>
      <inertial>
        <pose frame=''>0 0 0 0 -0 0</pose>
        <mass>10</mass>
        <inertia>
          <ixx>0.325</ixx>
          <ixy>0</ixy>
          <ixz>0</ixz>
          <iyy>0.325</iyy>
          <iyz>0</iyz>
          <izz>0.5354</izz>
        </inertia>
      </inertial>
      <collision name='rear_left_wheel_collision_collision'>
        <pose frame=''>0 0 0 0.314159 -0.157079 0.314159</pose>
        <geometry>
          <sphere>
            <radius>0.02</radius>
          </sphere>
        </geometry>
      </collision>
      <visual name='rear_left_wheel_visual_visual'>
        <pose frame=''>0 0 0 0.314159 -0.157079 0.314159</pose>
        <geometry>
          <cylinder>
            <length>0.01016</length>
            <radius>0.02</radius>
          </cylinder>
        </geometry>
      </visual>
    </link>
    <joint name='rear_left_wheel_joint' type='revolute'>
      <child>rear_left_wheel</child>
      <parent>chassis</parent>
      <axis>
        <xyz>-0.1 3e-07 -0.000019</xyz>
        <limit>
          <lower>-1e+16</lower>
          <upper>1e+16</upper>
        </limit>
        <dynamics>
          <spring_reference>0</spring_reference>
          <spring_stiffness>0</spring_stiffness>
        </dynamics>
        <use_parent_model_frame>1</use_parent_model_frame>
      </axis>
    </joint>
    <link name='rear_right_wheel'>
      <pose frame=''>0.05742 -0.065 0.0275 0.314159 0.000019 0.314159</pose>
      <inertial>
        <pose frame=''>0 0 0 0 -0 0</pose>
        <mass>10</mass>
        <inertia>
          <ixx>0.325</ixx>
          <ixy>0</ixy>
          <ixz>0</ixz>
          <iyy>0.325</iyy>
          <iyz>0</iyz>
          <izz>0.5354</izz>
        </inertia>
      </inertial>
      <collision name='rear_right_wheel_collision_collision'>
        <pose frame=''>0 0 0 0.314159 -0.157079 0.314159</pose>
        <geometry>
          <sphere>
            <radius>0.02</radius>
          </sphere>
        </geometry>
      </collision>
      <visual name='rear_right_wheel_visual_visual'>
        <pose frame=''>0 0 0 0.314159 -0.157079 0.314159</pose>
        <geometry>
          <cylinder>
            <length>0.01016</length>
            <radius>0.02</radius>
          </cylinder>
        </geometry>
      </visual>
    </link>
    <joint name='rear_right_wheel_joint' type='revolute'>
      <child>rear_right_wheel</child>
      <parent>chassis</parent>
      <axis>
        <xyz>-0.1 3e-07 -0.000019</xyz>
        <limit>
          <lower>-1e+16</lower>
          <upper>1e+16</upper>
        </limit>
        <dynamics>
          <spring_reference>0</spring_reference>
          <spring_stiffness>0</spring_stiffness>
        </dynamics>
        <use_parent_model_frame>1</use_parent_model_frame>
      </axis>
    </joint>
    <static>0</static>
    <plugin name='KarcherUrdfPlugin' filename='libKarcherUrdfPlugin.so'>
      <max_steer>0.442</max_steer>
      <max_speed>1.5278</max_speed>
      <fwheel_steering_p_gain>3</fwheel_steering_p_gain>
      <fwheel_steering_i_gain>4</fwheel_steering_i_gain>
      <fwheel_steering_d_gain>1</fwheel_steering_d_gain>
      <chassis_aero_force_gain>0.63045</chassis_aero_force_gain>
      <front_torque>0</front_torque>
      <back_torque>200</back_torque>
      <front_brake_torque>0</front_brake_torque>
      <back_brake_torque>200</back_brake_torque>
      <wheel_base>1.006</wheel_base>
      <rear_track>1.1494</rear_track>
    </plugin>
    <plugin name='gazebo_ros_control' filename='libgazebo_ros_control.so'>
      <robotNamespace>/karcher_urdf</robotNamespace>
    </plugin>
  </model>
</sdf>
